Workbook
Name AffectedAsset: #REF!
Name Attack: 'Reference - CVSSv3.0'!$B$6:$B$9
Name CIA: 'Reference - CVSSv3.0'!$B$15:$B$17
Name Comp: 'Reference - CVSSv3.0'!$E$6:$E$7
Name Priv: 'Reference - CVSSv3.0'!$H$6:$H$8
Name Scope: 'Reference - CVSSv3.0'!$B$21:$B$22
Name Ux: 'Reference - CVSSv3.0'!$L$6:$L$7

Sheet System & Asset Identification
A1: System & Asset Identification
A3: Medical Device / System: | C3: Knee Balancer
A4: Scope:
A5: Date: | C5: <2022-06-08>
A6: Conducted by: | C6: <SIVA KUMAR /Security / LTTS> <Author Name / Function / Organization>
A9: ID # | B9: Asset Type (Information/Physical) | C9: Asset | D9: Asset Description | E9: Comments
A10: A01 | B10: Physical asset | C10: Mobile Device (iPad, iPhone V8-13) | D10: iPhone/iPad is used for running the knee balancer application (currently V8-13 are supported)
A11: A02 | B11: Information asset | C11: User identity | D11: User tagged with Azure AD credentials for validation
A12: A03 | B12: Information asset | C12: Knee balancer application | D12: Knee balancer application is composed of 3rd party applications (binaries, frameworks, 3rd party components, etc..)
A13: A04 | B13: Information asset | C13: MAC/iOS operating system | D13: Information about internals of the system (Device identification, software versions, supported protocols, etc.)
A14: A05 | B14: Information asset | C14: Knee balancer supporting software components (binaries, frameworks, 3rd party components, etc..) | D14: Knee balancer application is composed of 3rd party applications (binaries, frameworks, 3rd party components, etc..)
A15: A06 | B15: Information asset | C15: MAKO Screen | D15: It provides input for the Knee Balancer application to generate solutions using algorithms
A16: A07 | B16: Information asset | C16: Log Files | D16: Log files supporting the application
A17: A08 | B17: Information asset | C17: Security keys, tokens, certificates | D17: Keys, tokens and certificates
A18: A09 | B18: Information asset | C18: Data at Rest | D18: Data used by the application
A19: A10 | B19: Information asset | C19: Data in Transit | D19: Sensitive data being transmitted
A20: A11 | B20: Information asset | C20: Cloud interface & Storage | D20: For storing blobs
A21: A12 | B21: Information asset | C21: Stryker IP data | D21: Algorithms used to generate the solutions
A22: A13 | B22: Information asset | C22: Stryker App store | D22: For authorized MPS users, Knee Balancer application can be downloaded from stryker app store
A30: Printed copies for reference only
B31: Stryker Confidential - This document contains information that is confidential and proprietary. Neither this document nor the information herein may be reproduced, used, or disclosed to or for the benefit of any third party without the prior written consent of Stryker.

Sheet Vulnerability Identification
A1: Vulnerability Identification
A4: Vuln. ID | B4: Vulnerability Description | C4: Applicable (Yes/No) | D4: Rationale (if Vulnerability not applicable)
A5: V01 | B5: Ineffective management of user related data (creds) | C5: No | D5: Knee balancer application leveraging the mobile login credentials and for upload feature Microsoft authentication gets leveraged
A6: V02 | B6: Improper Authentication in the application (single factor, no captcha, etc..) | C6: No | D6: Knee balancer application leveraging the mobile login credentials and for upload feature Microsoft authentication gets leveraged
A7: V03 | B7: Improper Input Validation (allowed range) | C7: Yes | D7: n/a
A8: V04 | B8: Improper Storage of Stryker IP data | C8: Yes | D8: n/a
A9: V05 | B9: Device deviated from the normal functionality (jailbroken) | C9: Yes | D9: n/a
A10: V06 | B10: Irregular upload of case data to cloud storage | C10: Yes | D10: n/a
A11: V07 | B11: Reveal/exposure of sensitive information (Stryker IP data) | C11: Yes | D11: n/a
A12: SBOM/SOUP
A13: V11 | B13: Unpatched operating system | C13: No | D13: Security Operations Manual
A14: V12 | B14: Unsafely compiled Application Binaries in Application | C14: Yes | D14: n/a
A15: V13 | B15: Ineffective patch management | C15: No | D15: Security Operations Manual
A16: V14 | B16: Lack of OS vulnerability management | C16: No | D16: Security Operations Manual
A17: V15 | B17: 3rd Party Component Dependency & Vulnerabilities in Application | C17: Yes | D17: n/a
A18: V16 | B18: Unrestricted access to the stored application resources | C18: Yes | D18: n/a
A19: V17 | B19: No Static Analysis for developed code & SCA for SOUP in Application | C19: Yes | D19: n/a
A20: Application Data Management
A21: V21 | B21: Unencrypted sensitive data at rest in all possible locations (Device, Cloud) | C21: Yes | D21: n/a
A22: V22 | B22: Unencrypted sensitive data in transit in all flow channels | C22: Yes | D22: n/a
A23: V23 | B23: Weak Encryption Implementation for data at rest and in transit tactical and design wise or Inadequate encryption strength | C23: Yes | D23: n/a
A24: V24 | B24: Use of a Broken or Risky Cryptographic Algorithm | C24: Yes | D24: n/a
A25: V25 | B25: Information Exposure Through Log Files | C25: Yes | D25: n/a
A26: V26 | B26: Absence of application (status/behavior) logs and audit logs | C26: Yes | D26: n/a
A27: V27 | B27: Log Files: Audit Log Manipulation, Log Injection-Tampering-Forging | C27: Yes | D27: n/a
A28: V28 | B28: Insecure Storage of Sensitive Information (Application data) | C28: Yes | D28: n/a
A29: V29 | B29: Insecure Storage of Sensitive Information (Stryker data - keys, certs, etc.) | C29: Yes | D29: n/a
A30: Application/Communication Management
A31: V31 | B31: Untrusted 3rd party applications installation from appstore | C31: No | D31: Security Operations Manual
A32: V32 | B32: No security applications (antivirus, etc..) running in the ipad/iphone | C32: No | D32: Security Operations Manual
A33: V33 | B33: Unrestricted Wifi communication with open/untrusted sources (app update) | C33: No | D33: Security Operations Manual
A34: V34 | B34: Unrestricted BT communication/transfer with multiple sources (app update) | C34: No | D34: Security Operations Manual
A35: InSecure Configurations of Resources
A36: V41 | B36: Malicious Software Download | C36: No | D36: Security Operations Manual
A37: V42 | B37: Malicious Automated Software Update | C37: No | D37: Security Operations Manual
A38: Blob Storage
A39: V51 | B39: Generating SAS with indefinite time period | C39: Yes | D39: n/a
A40: V52 | B40: Improper key management during SAS generation | C40: Yes | D40: n/a
A41: V53 | B41: Compromised SAS URL's for blob storage | C41: Yes | D41: n/a
A42: V54 | B42: Exertion of the confined storage limit | C42: Yes | D42: n/a
...

Sheet Threat Assessment
A1: Threat Assessment
A3: # | B3: Threat Event | C3: Description | D3: Threat Source | E3: In Scope (Yes/No) | F3: Rationale (if out of scope)
A4: T01 | B4: Deliver undirected malware | C4: For iPad/iPhone, the charging/USB interface is provided & this can be used to connect the OTG devices. Other Network Interfaces can also be used for injecting the malware. | D4: TSA-1 - Individual (Employees, Insider, Trusted Insider/Priveleged Insider) TSA-3 - Skript Kiddies | E4: No | F4: The trust boundary of this risk analysis is only permitted to application and hence not considering the mobile device
A5: T02 | B5: Deliver directed malware | C5: Threat source delivers malware on a removable media which was designed to exploit a known vulnerability of the existing Software. Directed attack on the Application using knowledge about the Application. | D5: TSA-2 Organization | E5: No | F5: The trust boundary of this risk analysis is only permitted to application and hence not considering the mobile device
A6: T03 | B6: Perform wireless perimeter network reconnaissance/scanning. | C6: Adversary uses commercial or free software to scan organizational perimeters to obtain a better understanding of the information technology infrastructure and improve the ability to launch successful attacks. | D6: TSA-3 - Skript Kiddies | E6: No | F6: The trust boundary of this risk analysis is only permitted to application and hence not considering the mobile device. Application has no web interface functionality
A7: T04 | B7: Unauthorized modifications to Knee Balancer Software | C7: Adversary gains unauthorized access to the system and removes or modifies application binaries. | D7: TSA-1 - Individual (Disgruntled/Ex-Employees, Outsider, Insider, Trusted Insider, Priveleged Insider) | E7: Yes | F7: n/a
A8: T05 | B8: Unauthorized access to Knee Balancer App | C8: Adversary gains unauthorized access to the system and removes or modifies application configuration and gains access | D8: TSA-3 - Skript Kiddies | E8: Yes | F8: n/a
A9: T06 | B9: Unauthorized access to app sensitive data (device's keys/certificates/crypto algorithms) | C9: Adversary gains unauthorized access to the Crypto keys and associated tokens, certificates | D9: TSA-3 - Skript Kiddies | E9: Yes | F9: n/a
A10: T07 | B10: Sensitive information exposure through audit log | C10: Sensitive information such as patient name, PHI data should not be revealed through audit log. Audit (log) data is considered as a sensitive data. It should be secured with proper access control | D10: TSA-1 - Individual (Disgruntled/Ex-Employees, Outsider, Insider, Trusted Insider, Priveleged Insider) | E10: Yes | F10: n/a
A11: T08 | B11: Improper access/modification of audit log | C11: Audit (log) data is considered as a sensitive data. It should be secured with proper access control | D11: TSA-1 - Individual (Disgruntled/Ex-Employees, Outsider, Insider, Trusted Insider, Priveleged Insider) | E11: Yes | F11: n/a
A12: T09 | B12: Corrupting the binaries/injecting malicious source code in Application | C12: Adversary identifies the binaries/source files supporting the application and tries to tamper for making the app unavailable | D12: TSA-3 - Skript Kiddies | E12: Yes | F12: n/a
A13: T10 | B13: Improper access/modification of Stryker IP data | C13: Adversary gains unauthorized access to the system and can remove/modify Stryker IP data | D13: TSA-2 Organization TSA-3 - Skript Kiddies | E13: Yes | F13: n/a
A14: T11 | B14: Improper validation/assessment of 3rd party components (libs, fw, etc..) | C14: All 3rd party components (libs, fw, etc…) should be validated properly related to the vulnerabilities and also their history of updates | D14: TSA-2 Organization | E14: Yes | F14: n/a
... A19: T16 | B19: Open to download (All stryker users) without restriction | C19: Only authorized MPS users should allow to download the knee balancer application | D19: TSA-1 - Individual (Employees, Insider, Trusted Insider/Priveleged Insider) | E19: Yes | F19: n/a
A21: Printed copies for reference only
B22: Stryker Confidential - This document contains information that is confidential and proprietary. Neither this document nor the information herein may be reproduced, used, or disclosed to or for the benefit of any third party without the prior written consent of Stryker.

Sheet Security Risk Assess
A1: Security Risk Assessment
F3: Adverse Impact | J3: Pre-Implementation of Security Controls | Z3: Security Controls/Mitigations | AC3: Post-Implementation of Security Controls
A4: ID # | B4: T ID | C4: Threat Event(s) | D4: V ID | E4: Vulnerabilities | F4: A ID | G4: Asset | H4: Impact Description | I4: Safety Impact (Risk ID# or N/A) | J4: Confidentiality | K4: Integrity | L4: Availability | M4: Attack Vector | N4: Attack Complexity | O4: Privileges Required | P4: User Interaction | Q4: Scope | R4: Exploitability Sub Score | S4: ISC Base | T4: Impact Sub Score | U4: CVSS v3.0 Base Score | V4: Threat Event Initiation | W4: Threat Event Initiation Score | X4: Overall Risk Score | Y4: Security Risk Level | Z4: Security Risk Control Measures | AA4: Implementation of Risk Control Measures | AB4: Verification of Risk Control Measures (Effectiveness) | AC4: ConfidentialityP | AD4: IntegrityP | AE4: AvailabilityP | AF4: Attack VectorP | AG4: Attack ComplexityP | AH4: Privileges RequiredP | AI4: User InteractionP | AJ4: ScopeP | AK4: Exploitability Sub ScoreP | AL4: ISC BaseP | AM4: Impact Sub ScoreP | AN4: CVSS v3.0 Base ScoreP | AO4: Overall Risk ScoreP | AP4: Security Risk LevelP | AQ4: Residual Security Risk Acceptability Justification
A5: 1 | B5: T01 | C5: =IF(VLOOKUP(Table4[[#This Row],[T ID]],Table5[#All],5,FALSE)="No","Not in scope",VLOOKUP(Table4[[#This Row],[T ID]],Table5[#All],2,FALSE)) -> Not in scope | D5: V15 | E5: =IF(VLOOKUP(Table4[[#This Row],[V ID]],Vulnerabilities[#All],3,FALSE)="No","Not in scope",VLOOKUP(Table4[[#This Row],[V ID]],Vulnerabilities[#All],2,FALSE)) -> 3rd Party Component Dependency & Vulnerabilities in Application | F5: A05 | G5: =VLOOKUP(Table4[[#This Row],[A ID]],Assets[#All],3,FALSE) -> Knee balancer supporting software components (binaries, frameworks, 3rd party components, etc..) | H5: As Knee Balancer is running on a mobile device, it is important to secure the wireless/Network interfaces on the host such as BT, Wifi & charging interface. Without restrictions, any device can be connected with the host & hence affect the application | J5: None | K5: None | L5: Low | M5: Local | N5: Low | O5: Low | P5: None | Q5: Unchanged | R5: =8.22*VLOOKUP(Table4[[#This Row],[Attack Vector]],'Reference - CVSSv3.0'!$B$6:$C$9,2,FALSE)*VLOOKUP(Table4[[#This Row],[Attack Complexity]],'Reference - CVSSv3.0'!$E$6:$F$7,2,FALSE)*(IF(Table4[[#This Row],[Scope]]="Unchanged",VLOOKUP(Table4[[#This Row],[Privileges Required]],'Reference - CVSSv3.0'!$H$6:$I$8,2,FALSE),IF(Table4[[#This Row],[Scope]]="Changed",VLOOKUP(Table4[[#This Row],[Privileges Required]],'Reference - CVSSv3.0'!$H$6:$J$8,3,FALSE),NA())))*VLOOKUP(Table4[[#This Row],[User Interaction]],'Reference - CVSSv3.0'!$L$6:$M$7,2,FALSE) -> 1.8345766 | S5: =(1 - ((1 - VLOOKUP(Table4[[#This Row],[Confidentiality]],'Reference - CVSSv3.0'!$B$15:$C$17,2,FALSE)) * (1 - VLOOKUP(Table4[[#This Row],[Integrity]],'Reference - CVSSv3.0'!$B$15:$C$17,2,FALSE)) * (1 - VLOOKUP(Table4[[#This Row],[Availability]],'Reference - CVSSv3.0'!$B$15:$C$17,2,FALSE)))) -> 0.22 | T5: =IF(Table4[[#This Row],[Scope]]="Unchanged",6.42*Table4[[#This Row],[ISC Base]],IF(Table4[[#This Row],[Scope]]="Changed",7.52*(Table4[[#This Row],[ISC Base]] - 0.029) - 3.25 * POWER(Table4[[#This Row],[ISC Base]] - 0.02,15),NA())) -> 1.4124 | U5: =IF(Table4[[#This Row],[Impact Sub Score]]<=0,0,IF(Table4[[#This Row],[Scope]]="Unchanged",ROUNDUP(MIN((Table4[[#This Row],[Impact Sub Score]]+Table4[[#This Row],[Exploitability Sub Score]]),10),1),IF(Table4[[#This Row],[Scope]]="Changed",ROUNDUP(MIN((1.08*(Table4[[#This Row],[Impact Sub Score]]+Table4[[#This Row],[Exploitability Sub Score]])),10),1),NA()))) -> 3.3 | V5: Low | W5: =VLOOKUP(Table4[[#This Row],[Threat Event Initiation]],NIST_Scale_LOAI[],2,FALSE) -> 0.2 | X5: =IF(Table4[[#This Row],[Impact Sub Score]]<=0,0,IF(Table4[[#This Row],[Scope]]="Unchanged",ROUNDUP(MIN((Table4[[#This Row],[Impact Sub Score]]+Table4[[#This Row],[Exploitability Sub Score]]*Table4[[#This Row],[Threat Event Initiation Score]]),10),1),IF(Table4[[#This Row],[Scope]]="Changed",ROUNDUP(MIN((1.08*(Table4[[#This Row],[Impact Sub Score]]+Table4[[#This Row],[Exploitability Sub Score]]*Table4[[#This Row],[Threat Event Initiation Score]])),10),1),NA()))) -> 1.8 | Y5: =IF(OR(ISBLANK(Table4[[#This Row],[Overall Risk Score]]),ISNA(Table4[[#This Row],[Overall Risk Score]])),"",IF(AND(Table4[[#This Row],[Overall Risk Score]]>=9,Table4[[#This Row],[Overall Risk Score]]<=10),"CRITICAL",IF(AND(Table4[[#This Row],[Overall Risk Score]]>=7,Table4[[#This Row],[Overall Risk Score]]<=8.9),"HIGH",IF(AND(Table4[[#This Row],[Overall Risk Score]]>=4,Table4[[#This Row],[Overall Risk Score]]<=6.9),"MEDIUM",IF(AND(Table4[[#This Row],[Overall Risk Score]]>=0.1,Table4[[#This Row],[Overall Risk Score]]<=3.9),"LOW","NONE"))))) -> LOW | AK5: =8.22*VLOOKUP(Table4[[#This Row],[Attack VectorP]],'Reference - CVSSv3.0'!$B$6:$C$9,2,FALSE)*VLOOKUP(Table4[[#This Row],[Attack ComplexityP]],'Reference - CVSSv3.0'!$E$6:$F$7,2,FALSE)*(IF(Table4[[#This Row],[ScopeP]]="Unchanged",VLOOKUP(Table4[[#This Row],[Privileges RequiredP]],'Reference - CVSSv3.0'!$H$6:$I$8,2,FALSE),IF(Table4[[#This Row],[ScopeP]]="Changed",VLOOKUP(Table4[[#This Row],[Privileges RequiredP]],'Reference - CVSSv3.0'!$H$6:$J$8,3,FALSE),NA())))*VLOOKUP(Table4[[#This Row],[User InteractionP]],'Reference - CVSSv3.0'!$L$6:$M$7,2,FALSE) -> #N/A | AL5: =(1 - ((1 - VLOOKUP(Table4[[#This Row],[ConfidentialityP]],'Reference - CVSSv3.0'!$B$15:$C$17,2,FALSE)) * (1 - VLOOKUP(Table4[[#This Row],[IntegrityP]],'Reference - CVSSv3.0'!$B$15:$C$17,2,FALSE)) * (1 - VLOOKUP(Table4[[#This Row],[AvailabilityP]],'Reference - CVSSv3.0'!$B$15:$C$17,2,FALSE)))) -> #N/A | AM5: =IF(Table4[[#This Row],[ScopeP]]="Unchanged",6.42*Table4[[#This Row],[ISC BaseP]],IF(Table4[[#This Row],[ScopeP]]="Changed",7.52*(Table4[[#This Row],[ISC BaseP]] - 0.029) - 3.25 * POWER(Table4[[#This Row],[ISC BaseP]] - 0.02,15),NA())) -> #N/A | AN5: =IF(Table4[[#This Row],[Impact Sub ScoreP]]<=0,0,IF(Table4[[#This Row],[ScopeP]]="Unchanged",ROUNDUP(MIN((Table4[[#This Row],[Impact Sub ScoreP]]+Table4[[#This Row],[Exploitability Sub ScoreP]]),10),1),IF(Table4[[#This Row],[ScopeP]]="Changed",ROUNDUP(MIN((1.08*(Table4[[#This Row],[Impact Sub ScoreP]]+Table4[[#This Row],[Exploitability Sub ScoreP]])),10),1),NA()))) -> #N/A | AO5: =IF(Table4[[#This Row],[Impact Sub ScoreP]]<=0,0,IF(Table4[[#This Row],[ScopeP]]="Unchanged",ROUNDUP(MIN((Table4[[#This Row],[Impact Sub ScoreP]]+Table4[[#This Row],[Exploitability Sub ScoreP]]*Table4[[#This Row],[Threat Event Initiation Score]]),10),1),IF(Table4[[#This Row],[ScopeP]]="Changed",ROUNDUP(MIN((1.08*(Table4[[#This Row],[Impact Sub ScoreP]]+Table4[[#This Row],[Exploitability Sub ScoreP]]*Table4[[#This Row],[Threat Event Initiation Score]])),10),1),NA()))) -> #N/A | AP5: =IF(OR(ISBLANK(Table4[[#This Row],[Overall Risk ScoreP]]),ISNA(Table4[[#This Row],[Overall Risk ScoreP]])),"",IF(AND(Table4[[#This Row],[Overall Risk ScoreP]]>=9,Table4[[#This Row],[Overall Risk ScoreP]]<=10),"CRITICAL",IF(AND(Table4[[#This Row],[Overall Risk ScoreP]]>=7,Table4[[#This Row],[Overall Risk ScoreP]]<=8.9),"HIGH",IF(AND(Table4[[#This Row],[Overall Risk ScoreP]]>=4,Table4[[#This Row],[Overall Risk ScoreP]]<=6.9),"MEDIUM",IF(AND(Table4[[#This Row],[Overall Risk ScoreP]]>=0.1,Table4[[#This Row],[Overall Risk ScoreP]]<=3.9),"LOW","NONE")))))
A6: 2 | B6: T01 | C6: =IF(VLOOKUP(Table4[[#This Row],[T ID]],Table5[#All],5,FALSE)="No","Not in scope",VLOOKUP(Table4[[#This Row],[T ID]],Table5[#All],2,FALSE)) -> Not in scope | D6: V31 | E6: =IF(VLOOKUP(Table4[[#This Row],[V ID]],Vulnerabilities[#All],3,FALSE)="No","Not in scope",VLOOKUP(Table4[[#This Row],[V ID]],Vulnerabilities[#All],2,FALSE)) -> Not in scope | F6: A01 | G6: =VLOOKUP(Table4[[#This Row],[A ID]],Assets[#All],3,FALSE) -> Mobile Device (iPad, iPhone V8-13) | H6: As Knee Balancer is running on a mobile device, it is important to secure the wireless interfaces on the host such as BT, Wifi. Without restrictions any device can be connected with the host | J6: None | K6: None | L6: Low | M6: Local | N6: Low | O6: Low | P6: None | Q6: Unchanged | R6: =8.22*VLOOKUP(Table4[[#This Row],[Attack Vector]],'Reference - CVSSv3.0'!$B$6:$C$9,2,FALSE)*VLOOKUP(Table4[[#This Row],[Attack Complexity]],'Reference - CVSSv3.0'!$E$6:$F$7,2,FALSE)*(IF(Table4[[#This Row],[Scope]]="Unchanged",VLOOKUP(Table4[[#This Row],[Privileges Required]],'Reference - CVSSv3.0'!$H$6:$I$8,2,FALSE),IF(Table4[[#This Row],[Scope]]="Changed",VLOOKUP(Table4[[#This Row],[Privileges Required]],'Reference - CVSSv3.0'!$H$6:$J$8,3,FALSE),NA())))*VLOOKUP(Table4[[#This Row],[User Interaction]],'Reference - CVSSv3.0'!$L$6:$M$7,2,FALSE) -> 1.8345766 | S6: =(1 - ((1 - VLOOKUP(Table4[[#This Row],[Confidentiality]],'Reference - CVSSv3.0'!$B$15:$C$17,2,FALSE)) * (1 - VLOOKUP(Table4[[#This Row],[Integrity]],'Reference - CVSSv3.0'!$B$15:$C$17,2,FALSE)) * (1 - VLOOKUP(Table4[[#This Row],[Availability]],'Reference - CVSSv3.0'!$B$15:$C$17,2,FALSE)))) -> 0.22 | T6: =IF(Table4[[#This Row],[Scope]]="Unchanged",6.42*Table4[[#This Row],[ISC Base]],IF(Table4[[#This Row],[Scope]]="Changed",7.52*(Table4[[#This Row],[ISC Base]] - 0.029) - 3.25 * POWER(Table4[[#This Row],[ISC Base]] - 0.02,15),NA())) -> 1.4124 | U6: =IF(Table4[[#This Row],[Impact Sub Score]]<=0,0,IF(Table4[[#This Row],[Scope]]="Unchanged",ROUNDUP(MIN((Table4[[#This Row],[Impact Sub Score]]+Table4[[#This Row],[Exploitability Sub Score]]),10),1),IF(Table4[[#This Row],[Scope]]="Changed",ROUNDUP(MIN((1.08*(Table4[[#This Row],[Impact Sub Score]]+Table4[[#This Row],[Exploitability Sub Score]])),10),1),NA()))) -> 3.3 | V6: Low | W6: =VLOOKUP(Table4[[#This Row],[Threat Event Initiation]],NIST_Scale_LOAI[],2,FALSE) -> 0.2 | X6: =IF(Table4[[#This Row],[Impact Sub Score]]<=0,0,IF(Table4[[#This Row],[Scope]]="Unchanged",ROUNDUP(MIN((Table4[[#This Row],[Impact Sub Score]]+Table4[[#This Row],[Exploitability Sub Score]]*Table4[[#This Row],[Threat Event Initiation Score]]),10),1),IF(Table4[[#This Row],[Scope]]="Changed",ROUNDUP(MIN((1.08*(Table4[[#This Row],[Impact Sub Score]]+Table4[[#This Row],[Exploitability Sub Score]]*Table4[[#This Row],[Threat Event Initiation Score]])),10),1),NA()))) -> 1.8 | Y6: =IF(OR(ISBLANK(Table4[[#This Row],[Overall Risk Score]]),ISNA(Table4[[#This Row],[Overall Risk Score]])),"",IF(AND(Table4[[#This Row],[Overall Risk Score]]>=9,Table4[[#This Row],[Overall Risk Score]]<=10),"CRITICAL",IF(AND(Table4[[#This Row],[Overall Risk Score]]>=7,Table4[[#This Row],[Overall Risk Score]]<=8.9),"HIGH",IF(AND(Table4[[#This Row],[Overall Risk Score]]>=4,Table4[[#This Row],[Overall Risk Score]]<=6.9),"MEDIUM",IF(AND(Table4[[#This Row],[Overall Risk Score]]>=0.1,Table4[[#This Row],[Overall Risk Score]]<=3.9),"LOW","NONE"))))) -> LOW | AK6: =8.22*VLOOKUP(Table4[[#This Row],[Attack VectorP]],'Reference - CVSSv3.0'!$B$6:$C$9,2,FALSE)*VLOOKUP(Table4[[#This Row],[Attack ComplexityP]],'Reference - CVSSv3.0'!$E$6:$F$7,2,FALSE)*(IF(Table4[[#This Row],[ScopeP]]="Unchanged",VLOOKUP(Table4[[#This Row],[Privileges RequiredP]],'Reference - CVSSv3.0'!$H$6:$I$8,2,FALSE),IF(Table4[[#This Row],[ScopeP]]="Changed",VLOOKUP(Table4[[#This Row],[Privileges RequiredP]],'Reference - CVSSv3.0'!$H$6:$J$8,3,FALSE),NA())))*VLOOKUP(Table4[[#This Row],[User InteractionP]],'Reference - CVSSv3.0'!$L$6:$M$7,2,FALSE) -> #N/A | AL6: =(1 - ((1 - VLOOKUP(Table4[[#This Row],[ConfidentialityP]],'Reference - CVSSv3.0'!$B$15:$C$17,2,FALSE)) * (1 - VLOOKUP(Table4[[#This Row],[IntegrityP]],'Reference - CVSSv3.0'!$B$15:$C$17,2,FALSE)) * (1 - VLOOKUP(Table4[[#This Row],[AvailabilityP]],'Reference - CVSSv3.0'!$B$15:$C$17,2,FALSE)))) -> #N/A | AM6: =IF(Table4[[#This Row],[ScopeP]]="Unchanged",6.42*Table4[[#This Row],[ISC BaseP]],IF(Table4[[#This Row],[ScopeP]]="Changed",7.52*(Table4[[#This Row],[ISC BaseP]] - 0.029) - 3.25 * POWER(Table4[[#This Row],[ISC BaseP]] - 0.02,15),NA())) -> #N/A | AN6: =IF(Table4[[#This Row],[Impact Sub ScoreP]]<=0,0,IF(Table4[[#This Row],[ScopeP]]="Unchanged",ROUNDUP(MIN((Table4[[#This Row],[Impact Sub ScoreP]]+Table4[[#This Row],[Exploitability Sub ScoreP]]),10),1),IF(Table4[[#This Row],[ScopeP]]="Changed",ROUNDUP(MIN((1.08*(Table4[[#This Row],[Impact Sub ScoreP]]+Table4[[#This Row],[Exploitability Sub ScoreP]])),10),1),NA()))) -> #N/A | AO6: =IF(Table4[[#This Row],[Impact Sub ScoreP]]<=0,0,IF(Table4[[#This Row],[ScopeP]]="Unchanged",ROUNDUP(MIN((Table4[[#This Row],[Impact Sub ScoreP]]+Table4[[#This Row],[Exploitability Sub ScoreP]]*Table4[[#This Row],[Threat Event Initiation Score]]),10),1),IF(Table4[[#This Row],[ScopeP]]="Changed",ROUNDUP(MIN((1.08*(Table4[[#This Row],[Impact Sub ScoreP]]+Table4[[#This Row],[Exploitability Sub ScoreP]]*Table4[[#This Row],[Threat Event Initiation Score]])),10),1),NA()))) -> #N/A | AP6: =IF(OR(ISBLANK(Table4[[#This Row],[Overall Risk ScoreP]]),ISNA(Table4[[#This Row],[Overall Risk ScoreP]])),"",IF(AND(Table4[[#This Row],[Overall Risk ScoreP]]>=9,Table4[[#This Row],[Overall Risk ScoreP]]<=10),"CRITICAL",IF(AND(Table4[[#This Row],[Overall Risk ScoreP]]>=7,Table4[[#This Row],[Overall Risk ScoreP]]<=8.9),"HIGH",IF(AND(Table4[[#This Row],[Overall Risk ScoreP]]>=4,Table4[[#This Row],[Overall Risk ScoreP]]<=6.9),"MEDIUM",IF(AND(Table4[[#This Row],[Overall Risk ScoreP]]>=0.1,Table4[[#This Row],[Overall Risk ScoreP]]<=3.9),"LOW","NONE")))))
A7: 3 | B7: T03 | C7: =IF(VLOOKUP(Table4[[#This Row],[T ID]],Table5[#All],5,FALSE)="No","Not in scope",VLOOKUP(Table4[[#This Row],[T ID]],Table5[#All],2,FALSE)) -> Not in scope | D7: V17 | E7: =IF(VLOOKUP(Table4[[#This Row],[V ID]],Vulnerabilities[#All],3,FALSE)="No","Not in scope",VLOOKUP(Table4[[#This Row],[V ID]],Vulnerabilities[#All],2,FALSE)) -> No Static Analysis for developed code & SCA for SOUP in Application | F7: A03 | G7: =VLOOKUP(Table4[[#This Row],[A ID]],Assets[#All],3,FALSE) -> Knee balancer application | H7: Open/Unrestricted Network interfaces are easy to exploit. Secure and hardened network elements protect the system from attacks. Code validation through static analysis required | J7: Low | K7: None | L7: Low | M7: Network | N7: High | O7: None | P7: None | Q7: Unchanged | R7: =8.22*VLOOKUP(Table4[[#This Row],[Attack Vector]],'Reference - CVSSv3.0'!$B$6:$C$9,2,FALSE)*VLOOKUP(Table4[[#This Row],[Attack Complexity]],'Reference - CVSSv3.0'!$E$6:$F$7,2,FALSE)*(IF(Table4[[#This Row],[Scope]]="Unchanged",VLOOKUP(Table4[[#This Row],[Privileges Required]],'Reference - CVSSv3.0'!$H$6:$I$8,2,FALSE),IF(Table4[[#This Row],[Scope]]="Changed",VLOOKUP(Table4[[#This Row],[Privileges Required]],'Reference - CVSSv3.0'!$H$6:$J$8,3,FALSE),NA())))*VLOOKUP(Table4[[#This Row],[User Interaction]],'Reference - CVSSv3.0'!$L$6:$M$7,2,FALSE) -> 2.2211673 | S7: =(1 - ((1 - VLOOKUP(Table4[[#This Row],[Confidentiality]],'Reference - CVSSv3.0'!$B$15:$C$17,2,FALSE)) * (1 - VLOOKUP(Table4[[#This Row],[Integrity]],'Reference - CVSSv3.0'!$B$15:$C$17,2,FALSE)) * (1 - VLOOKUP(Table4[[#This Row],[Availability]],'Reference - CVSSv3.0'!$B$15:$C$17,2,FALSE)))) -> 0.3916 | T7: =IF(Table4[[#This Row],[Scope]]="Unchanged",6.42*Table4[[#This Row],[ISC Base]],IF(Table4[[#This Row],[Scope]]="Changed",7.52*(Table4[[#This Row],[ISC Base]] - 0.029) - 3.25 * POWER(Table4[[#This Row],[ISC Base]] - 0.02,15),NA())) -> 2.514072 | U7: =IF(Table4[[#This Row],[Impact Sub Score]]<=0,0,IF(Table4[[#This Row],[Scope]]="Unchanged",ROUNDUP(MIN((Table4[[#This Row],[Impact Sub Score]]+Table4[[#This Row],[Exploitability Sub Score]]),10),1),IF(Table4[[#This Row],[Scope]]="Changed",ROUNDUP(MIN((1.08*(Table4[[#This Row],[Impact Sub Score]]+Table4[[#This Row],[Exploitability Sub Score]])),10),1),NA()))) -> 4.8 | V7: Moderate | W7: =VLOOKUP(Table4[[#This Row],[Threat Event Initiation]],NIST_Scale_LOAI[],2,FALSE) -> 0.5 | X7: =IF(Table4[[#This Row],[Impact Sub Score]]<=0,0,IF(Table4[[#This Row],[Scope]]="Unchanged",ROUNDUP(MIN((Table4[[#This Row],[Impact Sub Score]]+Table4[[#This Row],[Exploitability Sub Score]]*Table4[[#This Row],[Threat Event Initiation Score]]),10),1),IF(Table4[[#This Row],[Scope]]="Changed",ROUNDUP(MIN((1.08*(Table4[[#This Row],[Impact Sub Score]]+Table4[[#This Row],[Exploitability Sub Score]]*Table4[[#This Row],[Threat Event Initiation Score]])),10),1),NA()))) -> 3.7 | Y7: =IF(OR(ISBLANK(Table4[[#This Row],[Overall Risk Score]]),ISNA(Table4[[#This Row],[Overall Risk Score]])),"",IF(AND(Table4[[#This Row],[Overall Risk Score]]>=9,Table4[[#This Row],[Overall Risk Score]]<=10),"CRITICAL",IF(AND(Table4[[#This Row],[Overall Risk Score]]>=7,Table4[[#This Row],[Overall Risk Score]]<=8.9),"HIGH",IF(AND(Table4[[#This Row],[Overall Risk Score]]>=4,Table4[[#This Row],[Overall Risk Score]]<=6.9),"MEDIUM",IF(AND(Table4[[#This Row],[Overall Risk Score]]>=0.1,Table4[[#This Row],[Overall Risk Score]]<=3.9),"LOW","NONE"))))) -> LOW | AK7: =8.22*VLOOKUP(Table4[[#This Row],[Attack VectorP]],'Reference - CVSSv3.0'!$B$6:$C$9,2,FALSE)*VLOOKUP(Table4[[#This Row],[Attack ComplexityP]],'Reference - CVSSv3.0'!$E$6:$F$7,2,FALSE)*(IF(Table4[[#This Row],[ScopeP]]="Unchanged",VLOOKUP(Table4[[#This Row],[Privileges RequiredP]],'Reference - CVSSv3.0'!$H$6:$I$8,2,FALSE),IF(Table4[[#This Row],[ScopeP]]="Changed",VLOOKUP(Table4[[#This Row],[Privileges RequiredP]],'Reference - CVSSv3.0'!$H$6:$J$8,3,FALSE),NA())))*VLOOKUP(Table4[[#This Row],[User InteractionP]],'Reference - CVSSv3.0'!$L$6:$M$7,2,FALSE) -> #N/A | AL7: =(1 - ((1 - VLOOKUP(Table4[[#This Row],[ConfidentialityP]],'Reference - CVSSv3.0'!$B$15:$C$17,2,FALSE)) * (1 - VLOOKUP(Table4[[#This Row],[IntegrityP]],'Reference - CVSSv3.0'!$B$15:$C$17,2,FALSE)) * (1 - VLOOKUP(Table4[[#This Row],[AvailabilityP]],'Reference - CVSSv3.0'!$B$15:$C$17,2,FALSE)))) -> #N/A | AM7: =IF(Table4[[#This Row],[ScopeP]]="Unchanged",6.42*Table4[[#This Row],[ISC BaseP]],IF(Table4[[#This Row],[ScopeP]]="Changed",7.52*(Table4[[#This Row],[ISC BaseP]] - 0.029) - 3.25 * POWER(Table4[[#This Row],[ISC BaseP]] - 0.02,15),NA())) -> #N/A | AN7: =IF(Table4[[#This Row],[Impact Sub ScoreP]]<=0,0,IF(Table4[[#This Row],[ScopeP]]="Unchanged",ROUNDUP(MIN((Table4[[#This Row],[Impact Sub ScoreP]]+Table4[[#This Row],[Exploitability Sub ScoreP]]),10),1),IF(Table4[[#This Row],[ScopeP]]="Changed",ROUNDUP(MIN((1.08*(Table4[[#This Row],[Impact Sub ScoreP]]+Table4[[#This Row],[Exploitability Sub ScoreP]])),10),1),NA()))) -> #N/A | AO7: =IF(Table4[[#This Row],[Impact Sub ScoreP]]<=0,0,IF(Table4[[#This Row],[ScopeP]]="Unchanged",ROUNDUP(MIN((Table4[[#This Row],[Impact Sub ScoreP]]+Table4[[#This Row],[Exploitability Sub ScoreP]]*Table4[[#This Row],[Threat Event Initiation Score]]),10),1),IF(Table4[[#This Row],[ScopeP]]="Changed",ROUNDUP(MIN((1.08*(Table4[[#This Row],[Impact Sub ScoreP]]+Table4[[#This Row],[Exploitability Sub ScoreP]]*Table4[[#This Row],[Threat Event Initiation Score]])),10),1),NA()))) -> #N/A | AP7: =IF(OR(ISBLANK(Table4[[#This Row],[Overall Risk ScoreP]]),ISNA(Table4[[#This Row],[Overall Risk ScoreP]])),"",IF(AND(Table4[[#This Row],[Overall Risk ScoreP]]>=9,Table4[[#This Row],[Overall Risk ScoreP]]<=10),"CRITICAL",IF(AND(Table4[[#This Row],[Overall Risk ScoreP]]>=7,Table4[[#This Row],[Overall Risk ScoreP]]<=8.9),"HIGH",IF(AND(Table4[[#This Row],[Overall Risk ScoreP]]>=4,Table4[[#This Row],[Overall Risk ScoreP]]<=6.9),"MEDIUM",IF(AND(Table4[[#This Row],[Overall Risk ScoreP]]>=0.1,Table4[[#This Row],[Overall Risk ScoreP]]<=3.9),"LOW","NONE")))))
A8: 4 | B8: T04 | C8: =IF(VLOOKUP(Table4[[#This Row],[T ID]],Table5[#All],5,FALSE)="No","Not in scope",VLOOKUP(Table4[[#This Row],[T ID]],Table5[#All],2,FALSE)) -> Unauthorized modifications to Knee Balancer Software | D8: V12 | E8: =IF(VLOOKUP(Table4[[#This Row],[V ID]],Vulnerabilities[#All],3,FALSE)="No","Not in scope",VLOOKUP(Table4[[#This Row],[V ID]],Vulnerabilities[#All],2,FALSE)) -> Unsafely compiled Application Binaries in Application | F8: A05 | G8: =VLOOKUP(Table4[[#This Row],[A ID]],Assets[#All],3,FALSE) -> Knee balancer supporting software components (binaries, frameworks, 3rd party components, etc..) | H8: If the software components are not protected properly/exposed for access inside the mobile host with unrestricted/unauthorized access, then the modification/tampering of the software can lead to the unavailability of the application | J8: None | K8: High | L8: Low | M8: Local | N8: Low | O8: Low | P8: None | Q8: Unchanged | R8: =8.22*VLOOKUP(Table4[[#This Row],[Attack Vector]],'Reference - CVSSv3.0'!$B$6:$C$9,2,FALSE)*VLOOKUP(Table4[[#This Row],[Attack Complexity]],'Reference - CVSSv3.0'!$E$6:$F$7,2,FALSE)*(IF(Table4[[#This Row],[Scope]]="Unchanged",VLOOKUP(Table4[[#This Row],[Privileges Required]],'Reference - CVSSv3.0'!$H$6:$I$8,2,FALSE),IF(Table4[[#This Row],[Scope]]="Changed",VLOOKUP(Table4[[#This Row],[Privileges Required]],'Reference - CVSSv3.0'!$H$6:$J$8,3,FALSE),NA())))*VLOOKUP(Table4[[#This Row],[User Interaction]],'Reference - CVSSv3.0'!$L$6:$M$7,2,FALSE) -> 1.8345766 | S8: =(1 - ((1 - VLOOKUP(Table4[[#This Row],[Confidentiality]],'Reference - CVSSv3.0'!$B$15:$C$17,2,FALSE)) * (1 - VLOOKUP(Table4[[#This Row],[Integrity]],'Reference - CVSSv3.0'!$B$15:$C$17,2,FALSE)) * (1 - VLOOKUP(Table4[[#This Row],[Availability]],'Reference - CVSSv3.0'!$B$15:$C$17,2,FALSE)))) -> 0.6568 | T8: =IF(Table4[[#This Row],[Scope]]="Unchanged",6.42*Table4[[#This Row],[ISC Base]],IF(Table4[[#This Row],[Scope]]="Changed",7.52*(Table4[[#This Row],[ISC Base]] - 0.029) - 3.25 * POWER(Table4[[#This Row],[ISC Base]] - 0.02,15),NA())) -> 4.216656 | U8: =IF(Table4[[#This Row],[Impact Sub Score]]<=0,0,IF(Table4[[#This Row],[Scope]]="Unchanged",ROUNDUP(MIN((Table4[[#This Row],[Impact Sub Score]]+Table4[[#This Row],[Exploitability Sub Score]]),10),1),IF(Table4[[#This Row],[Scope]]="Changed",ROUNDUP(MIN((1.08*(Table4[[#This Row],[Impact Sub Score]]+Table4[[#This Row],[Exploitability Sub Score]])),10),1),NA()))) -> 6.1 | V8: Moderate | W8: =VLOOKUP(Table4[[#This Row],[Threat Event Initiation]],NIST_Scale_LOAI[],2,FALSE) -> 0.5 | X8: =IF(Table4[[#This Row],[Impact Sub Score]]<=0,0,IF(Table4[[#This Row],[Scope]]="Unchanged",ROUNDUP(MIN((Table4[[#This Row],[Impact Sub Score]]+Table4[[#This Row],[Exploitability Sub Score]]*Table4[[#This Row],[Threat Event Initiation Score]]),10),1),IF(Table4[[#This Row],[Scope]]="Changed",ROUNDUP(MIN((1.08*(Table4[[#This Row],[Impact Sub Score]]+Table4[[#This Row],[Exploitability Sub Score]]*Table4[[#This Row],[Threat Event Initiation Score]])),10),1),NA()))) -> 5.2 | Y8: =IF(OR(ISBLANK(Table4[[#This Row],[Overall Risk Score]]),ISNA(Table4[[#This Row],[Overall Risk Score]])),"",IF(AND(Table4[[#This Row],[Overall Risk Score]]>=9,Table4[[#This Row],[Overall Risk Score]]<=10),"CRITICAL",IF(AND(Table4[[#This Row],[Overall Risk Score]]>=7,Table4[[#This Row],[Overall Risk Score]]<=8.9),"HIGH",IF(AND(Table4[[#This Row],[Overall Risk Score]]>=4,Table4[[#This Row],[Overall Risk Score]]<=6.9),"MEDIUM",IF(AND(Table4[[#This Row],[Overall Risk Score]]>=0.1,Table4[[#This Row],[Overall Risk Score]]<=3.9),"LOW","NONE"))))) -> MEDIUM | AK8: =8.22*VLOOKUP(Table4[[#This Row],[Attack VectorP]],'Reference - CVSSv3.0'!$B$6:$C$9,2,FALSE)*VLOOKUP(Table4[[#This Row],[Attack ComplexityP]],'Reference - CVSSv3.0'!$E$6:$F$7,2,FALSE)*(IF(Table4[[#This Row],[ScopeP]]="Unchanged",VLOOKUP(Table4[[#This Row],[Privileges RequiredP]],'Reference - CVSSv3.0'!$H$6:$I$8,2,FALSE),IF(Table4[[#This Row],[ScopeP]]="Changed",VLOOKUP(Table4[[#This Row],[Privileges RequiredP]],'Reference - CVSSv3.0'!$H$6:$J$8,3,FALSE),NA())))*VLOOKUP(Table4[[#This Row],[User InteractionP]],'Reference - CVSSv3.0'!$L$6:$M$7,2,FALSE) -> #N/A | AL8: =(1 - ((1 - VLOOKUP(Table4[[#This Row],[ConfidentialityP]],'Reference - CVSSv3.0'!$B$15:$C$17,2,FALSE)) * (1 - VLOOKUP(Table4[[#This Row],[IntegrityP]],'Reference - CVSSv3.0'!$B$15:$C$17,2,FALSE)) * (1 - VLOOKUP(Table4[[#This Row],[AvailabilityP]],'Reference - CVSSv3.0'!$B$15:$C$17,2,FALSE)))) -> #N/A | AM8: =IF(Table4[[#This Row],[ScopeP]]="Unchanged",6.42*Table4[[#This Row],[ISC BaseP]],IF(Table4[[#This Row],[ScopeP]]="Changed",7.52*(Table4[[#This Row],[ISC BaseP]] - 0.029) - 3.25 * POWER(Table4[[#This Row],[ISC BaseP]] - 0.02,15),NA())) -> #N/A | AN8: =IF(Table4[[#This Row],[Impact Sub ScoreP]]<=0,0,IF(Table4[[#This Row],[ScopeP]]="Unchanged",ROUNDUP(MIN((Table4[[#This Row],[Impact Sub ScoreP]]+Table4[[#This Row],[Exploitability Sub ScoreP]]),10),1),IF(Table4[[#This Row],[ScopeP]]="Changed",ROUNDUP(MIN((1.08*(Table4[[#This Row],[Impact Sub ScoreP]]+Table4[[#This Row],[Exploitability Sub ScoreP]])),10),1),NA()))) -> #N/A | AO8: =IF(Table4[[#This Row],[Impact Sub ScoreP]]<=0,0,IF(Table4[[#This Row],[ScopeP]]="Unchanged",ROUNDUP(MIN((Table4[[#This Row],[Impact Sub ScoreP]]+Table4[[#This Row],[Exploitability Sub ScoreP]]*Table4[[#This Row],[Threat Event Initiation Score]]),10),1),IF(Table4[[#This Row],[ScopeP]]="Changed",ROUNDUP(MIN((1.08*(Table4[[#This Row],[Impact Sub ScoreP]]+Table4[[#This Row],[Exploitability Sub ScoreP]]*Table4[[#This Row],[Threat Event Initiation Score]])),10),1),NA()))) -> #N/A | AP8: =IF(OR(ISBLANK(Table4[[#This Row],[Overall Risk ScoreP]]),ISNA(Table4[[#This Row],[Overall Risk ScoreP]])),"",IF(AND(Table4[[#This Row],[Overall Risk ScoreP]]>=9,Table4[[#This Row],[Overall Risk ScoreP]]<=10),"CRITICAL",IF(AND(Table4[[#This Row],[Overall Risk ScoreP]]>=7,Table4[[#This Row],[Overall Risk ScoreP]]<=8.9),"HIGH",IF(AND(Table4[[#This Row],[Overall Risk ScoreP]]>=4,Table4[[#This Row],[Overall Risk ScoreP]]<=6.9),"MEDIUM",IF(AND(Table4[[#This Row],[Overall Risk ScoreP]]>=0.1,Table4[[#This Row],[Overall Risk ScoreP]]<=3.9),"LOW","NONE")))))
A9: 5 | B9: T04 | C9: =IF(VLOOKUP(Table4[[#This Row],[T ID]],Table5[#All],5,FALSE)="No","Not in scope",VLOOKUP(Table4[[#This Row],[T ID]],Table5[#All],2,FALSE)) -> Unauthorized modifications to Knee Balancer Software | D9: V15 | E9: =IF(VLOOKUP(Table4[[#This Row],[V ID]],Vulnerabilities[#All],3,FALSE)="No","Not in scope",VLOOKUP(Table4[[#This Row],[V ID]],Vulnerabilities[#All],2,FALSE)) -> 3rd Party Component Dependency & Vulnerabilities in Application | F9: A05 | G9: =VLOOKUP(Table4[[#This Row],[A ID]],Assets[#All],3,FALSE) -> Knee balancer supporting software components (binaries, frameworks, 3rd party components, etc..) | H9: If the software components are not protected properly/exposed for access inside the mobile host with unrestricted/unauthorized access, then the modification/tampering of the software can lead to the unavailability of the application | J9: None | K9: High | L9: Low | M9: Local | N9: Low | O9: Low | P9: None | Q9: Unchanged | R9: =8.22*VLOOKUP(Table4[[#This Row],[Attack Vector]],'Reference - CVSSv3.0'!$B$6:$C$9,2,FALSE)*VLOOKUP(Table4[[#This Row],[Attack Complexity]],'Reference - CVSSv3.0'!$E$6:$F$7,2,FALSE)*(IF(Table4[[#This Row],[Scope]]="Unchanged",VLOOKUP(Table4[[#This Row],[Privileges Required]],'Reference - CVSSv3.0'!$H$6:$I$8,2,FALSE),IF(Table4[[#This Row],[Scope]]="Changed",VLOOKUP(Table4[[#This Row],[Privileges Required]],'Reference - CVSSv3.0'!$H$6:$J$8,3,FALSE),NA())))*VLOOKUP(Table4[[#This Row],[User Interaction]],'Reference - CVSSv3.0'!$L$6:$M$7,2,FALSE) -> 1.8345766 | S9: =(1 - ((1 - VLOOKUP(Table4[[#This Row],[Confidentiality]],'Reference - CVSSv3.0'!$B$15:$C$17,2,FALSE)) * (1 - VLOOKUP(Table4[[#This Row],[Integrity]],'Reference - CVSSv3.0'!$B$15:$C$17,2,FALSE)) * (1 - VLOOKUP(Table4[[#This Row],[Availability]],'Reference - CVSSv3.0'!$B$15:$C$17,2,FALSE)))) -> 0.6568 | T9: =IF(Table4[[#This Row],[Scope]]="Unchanged",6.42*Table4[[#This Row],[ISC Base]],IF(Table4[[#This Row],[Scope]]="Changed",7.52*(Table4[[#This Row],[ISC Base]] - 0.029) - 3.25 * POWER(Table4[[#This Row],[ISC Base]] - 0.02,15),NA())) -> 4.216656 | U9: =IF(Table4[[#This Row],[Impact Sub Score]]<=0,0,IF(Table4[[#This Row],[Scope]]="Unchanged",ROUNDUP(MIN((Table4[[#This Row],[Impact Sub Score]]+Table4[[#This Row],[Exploitability Sub Score]]),10),1),IF(Table4[[#This Row],[Scope]]="Changed",ROUNDUP(MIN((1.08*(Table4[[#This Row],[Impact Sub Score]]+Table4[[#This Row],[Exploitability Sub Score]])),10),1),NA()))) -> 6.1 | V9: Moderate | W9: =VLOOKUP(Table4[[#This Row],[Threat Event Initiation]],NIST_Scale_LOAI[],2,FALSE) -> 0.5 | X9: =IF(Table4[[#This Row],[Impact Sub Score]]<=0,0,IF(Table4[[#This Row],[Scope]]="Unchanged",ROUNDUP(MIN((Table4[[#This Row],[Impact Sub Score]]+Table4[[#This Row],[Exploitability Sub Score]]*Table4[[#This Row],[Threat Event Initiation Score]]),10),1),IF(Table4[[#This Row],[Scope]]="Changed",ROUNDUP(MIN((1.08*(Table4[[#This Row],[Impact Sub Score]]+Table4[[#This Row],[Exploitability Sub Score]]*Table4[[#This Row],[Threat Event Initiation Score]])),10),1),NA()))) -> 5.2 | Y9: =IF(OR(ISBLANK(Table4[[#This Row],[Overall Risk Score]]),ISNA(Table4[[#This Row],[Overall Risk Score]])),"",IF(AND(Table4[[#This Row],[Overall Risk Score]]>=9,Table4[[#This Row],[Overall Risk Score]]<=10),"CRITICAL",IF(AND(Table4[[#This Row],[Overall Risk Score]]>=7,Table4[[#This Row],[Overall Risk Score]]<=8.9),"HIGH",IF(AND(Table4[[#This Row],[Overall Risk Score]]>=4,Table4[[#This Row],[Overall Risk Score]]<=6.9),"MEDIUM",IF(AND(Table4[[#This Row],[Overall Risk Score]]>=0.1,Table4[[#This Row],[Overall Risk Score]]<=3.9),"LOW","NONE"))))) -> MEDIUM | AK9: =8.22*VLOOKUP(Table4[[#This Row],[Attack VectorP]],'Reference - CVSSv3.0'!$B$6:$C$9,2,FALSE)*VLOOKUP(Table4[[#This Row],[Attack ComplexityP]],'Reference - CVSSv3.0'!$E$6:$F$7,2,FALSE)*(IF(Table4[[#This Row],[ScopeP]]="Unchanged",VLOOKUP(Table4[[#This Row],[Privileges RequiredP]],'Reference - CVSSv3.0'!$H$6:$I$8,2,FALSE),IF(Table4[[#This Row],[ScopeP]]="Changed",VLOOKUP(Table4[[#This Row],[Privileges RequiredP]],'Reference - CVSSv3.0'!$H$6:$J$8,3,FALSE),NA())))*VLOOKUP(Table4[[#This Row],[User InteractionP]],'Reference - CVSSv3.0'!$L$6:$M$7,2,FALSE) -> #N/A | AL9: =(1 - ((1 - VLOOKUP(Table4[[#This Row],[ConfidentialityP]],'Reference - CVSSv3.0'!$B$15:$C$17,2,FALSE)) * (1 - VLOOKUP(Table4[[#This Row],[IntegrityP]],'Reference - CVSSv3.0'!$B$15:$C$17,2,FALSE)) * (1 - VLOOKUP(Table4[[#This Row],[AvailabilityP]],'Reference - CVSSv3.0'!$B$15:$C$17,2,FALSE)))) -> #N/A | AM9: =IF(Table4[[#This Row],[ScopeP]]="Unchanged",6.42*Table4[[#This Row],[ISC BaseP]],IF(Table4[[#This Row],[ScopeP]]="Changed",7.52*(Table4[[#This Row],[ISC BaseP]] - 0.029) - 3.25 * POWER(Table4[[#This Row],[ISC BaseP]] - 0.02,15),NA())) -> #N/A | AN9: =IF(Table4[[#This Row],[Impact Sub ScoreP]]<=0,0,IF(Table4[[#This Row],[ScopeP]]="Unchanged",ROUNDUP(MIN((Table4[[#This Row],[Impact Sub ScoreP]]+Table4[[#This Row],[Exploitability Sub ScoreP]]),10),1),IF(Table4[[#This Row],[ScopeP]]="Changed",ROUNDUP(MIN((1.08*(Table4[[#This Row],[Impact Sub ScoreP]]+Table4[[#This Row],[Exploitability Sub ScoreP]])),10),1),NA()))) -> #N/A | AO9: =IF(Table4[[#This Row],[Impact Sub ScoreP]]<=0,0,IF(Table4[[#This Row],[ScopeP]]="Unchanged",ROUNDUP(MIN((Table4[[#This Row],[Impact Sub ScoreP]]+Table4[[#This Row],[Exploitability Sub ScoreP]]*Table4[[#This Row],[Threat Event Initiation Score]]),10),1),IF(Table4[[#This Row],[ScopeP]]="Changed",ROUNDUP(MIN((1.08*(Table4[[#This Row],[Impact Sub ScoreP]]+Table4[[#This Row],[Exploitability Sub ScoreP]]*Table4[[#This Row],[Threat Event Initiation Score]])),10),1),NA()))) -> #N/A | AP9: =IF(OR(ISBLANK(Table4[[#This Row],[Overall Risk ScoreP]]),ISNA(Table4[[#This Row],[Overall Risk ScoreP]])),"",IF(AND(Table4[[#This Row],[Overall Risk ScoreP]]>=9,Table4[[#This Row],[Overall Risk ScoreP]]<=10),"CRITICAL",IF(AND(Table4[[#This Row],[Overall Risk ScoreP]]>=7,Table4[[#This Row],[Overall Risk ScoreP]]<=8.9),"HIGH",IF(AND(Table4[[#This Row],[Overall Risk ScoreP]]>=4,Table4[[#This Row],[Overall Risk ScoreP]]<=6.9),"MEDIUM",IF(AND(Table4[[#This Row],[Overall Risk ScoreP]]>=0.1,Table4[[#This Row],[Overall Risk ScoreP]]<=3.9),"LOW","NONE")))))
A10: 6 | B10: T04 | C10: =IF(VLOOKUP(Table4[[#This Row],[T ID]],Table5[#All],5,FALSE)="No","Not in scope",VLOOKUP(Table4[[#This Row],[T ID]],Table5[#All],2,FALSE)) -> Unauthorized modifications to Knee Balancer Software | D10: V16 | E10: =IF(VLOOKUP(Table4[[#This Row],[V ID]],Vulnerabilities[#All],3,FALSE)="No","Not in scope",VLOOKUP(Table4[[#This Row],[V ID]],Vulnerabilities[#All],2,FALSE)) -> Unrestricted access to the stored application resources | F10: A05 | G10: =VLOOKUP(Table4[[#This Row],[A ID]],Assets[#All],3,FALSE) -> Knee balancer supporting software components (binaries, frameworks, 3rd party components, etc..) | H10: If the software components are not protected properly/exposed for access inside the mobile host with unrestricted/unauthorized access, then the modification/tampering of the software can lead to the unavailability of the application | J10: None | K10: High | L10: Low | M10: Local | N10: Low | O10: Low | P10: None | Q10: Unchanged | R10: =8.22*VLOOKUP(Table4[[#This Row],[Attack Vector]],'Reference - CVSSv3.0'!$B$6:$C$9,2,FALSE)*VLOOKUP(Table4[[#This Row],[Attack Complexity]],'Reference - CVSSv3.0'!$E$6:$F$7,2,FALSE)*(IF(Table4[[#This Row],[Scope]]="Unchanged",VLOOKUP(Table4[[#This Row],[Privileges Required]],'Reference - CVSSv3.0'!$H$6:$I$8,2,FALSE),IF(Table4[[#This Row],[Scope]]="Changed",VLOOKUP(Table4[[#This Row],[Privileges Required]],'Reference - CVSSv3.0'!$H$6:$J$8,3,FALSE),NA())))*VLOOKUP(Table4[[#This Row],[User Interaction]],'Reference - CVSSv3.0'!$L$6:$M$7,2,FALSE) -> 1.8345766 | S10: =(1 - ((1 - VLOOKUP(Table4[[#This Row],[Confidentiality]],'Reference - CVSSv3.0'!$B$15:$C$17,2,FALSE)) * (1 - VLOOKUP(Table4[[#This Row],[Integrity]],'Reference - CVSSv3.0'!$B$15:$C$17,2,FALSE)) * (1 - VLOOKUP(Table4[[#This Row],[Availability]],'Reference - CVSSv3.0'!$B$15:$C$17,2,FALSE)))) -> 0.6568 | T10: =IF(Table4[[#This Row],[Scope]]="Unchanged",6.42*Table4[[#This Row],[ISC Base]],IF(Table4[[#This Row],[Scope]]="Changed",7.52*(Table4[[#This Row],[ISC Base]] - 0.029) - 3.25 * POWER(Table4[[#This Row],[ISC Base]] - 0.02,15),NA())) -> 4.216656 | U10: =IF(Table4[[#This Row],[Impact Sub Score]]<=0,0,IF(Table4[[#This Row],[Scope]]="Unchanged",ROUNDUP(MIN((Table4[[#This Row],[Impact Sub Score]]+Table4[[#This Row],[Exploitability Sub Score]]),10),1),IF(Table4[[#This Row],[Scope]]="Changed",ROUNDUP(MIN((1.08*(Table4[[#This Row],[Impact Sub Score]]+Table4[[#This Row],[Exploitability Sub Score]])),10),1),NA()))) -> 6.1 | V10: Moderate | W10: =VLOOKUP(Table4[[#This Row],[Threat Event Initiation]],NIST_Scale_LOAI[],2,FALSE) -> 0.5 | X10: =IF(Table4[[#This Row],[Impact Sub Score]]<=0,0,IF(Table4[[#This Row],[Scope]]="Unchanged",ROUNDUP(MIN((Table4[[#This Row],[Impact Sub Score]]+Table4[[#This Row],[Exploitability Sub Score]]*Table4[[#This Row],[Threat Event Initiation Score]]),10),1),IF(Table4[[#This Row],[Scope]]="Changed",ROUNDUP(MIN((1.08*(Table4[[#This Row],[Impact Sub Score]]+Table4[[#This Row],[Exploitability Sub Score]]*Table4[[#This Row],[Threat Event Initiation Score]])),10),1),NA()))) -> 5.2 | Y10: =IF(OR(ISBLANK(Table4[[#This Row],[Overall Risk Score]]),ISNA(Table4[[#This Row],[Overall Risk Score]])),"",IF(AND(Table4[[#This Row],[Overall Risk Score]]>=9,Table4[[#This Row],[Overall Risk Score]]<=10),"CRITICAL",IF(AND(Table4[[#This Row],[Overall Risk Score]]>=7,Table4[[#This Row],[Overall Risk Score]]<=8.9),"HIGH",IF(AND(Table4[[#This Row],[Overall Risk Score]]>=4,Table4[[#This Row],[Overall Risk Score]]<=6.9),"MEDIUM",IF(AND(Table4[[#This Row],[Overall Risk Score]]>=0.1,Table4[[#This Row],[Overall Risk Score]]<=3.9),"LOW","NONE"))))) -> MEDIUM | AK10: =8.22*VLOOKUP(Table4[[#This Row],[Attack VectorP]],'Reference - CVSSv3.0'!$B$6:$C$9,2,FALSE)*VLOOKUP(Table4[[#This Row],[Attack ComplexityP]],'Reference - CVSSv3.0'!$E$6:$F$7,2,FALSE)*(IF(Table4[[#This Row],[ScopeP]]="Unchanged",VLOOKUP(Table4[[#This Row],[Privileges RequiredP]],'Reference - CVSSv3.0'!$H$6:$I$8,2,FALSE),IF(Table4[[#This Row],[ScopeP]]="Changed",VLOOKUP(Table4[[#This Row],[Privileges RequiredP]],'Reference - CVSSv3.0'!$H$6:$J$8,3,FALSE),NA())))*VLOOKUP(Table4[[#This Row],[User InteractionP]],'Reference - CVSSv3.0'!$L$6:$M$7,2,FALSE) -> #N/A | AL10: =(1 - ((1 - VLOOKUP(Table4[[#This Row],[ConfidentialityP]],'Reference - CVSSv3.0'!$B$15:$C$17,2,FALSE)) * (1 - VLOOKUP(Table4[[#This Row],[IntegrityP]],'Reference - CVSSv3.0'!$B$15:$C$17,2,FALSE)) * (1 - VLOOKUP(Table4[[#This Row],[AvailabilityP]],'Reference - CVSSv3.0'!$B$15:$C$17,2,FALSE)))) -> #N/A | AM10: =IF(Table4[[#This Row],[ScopeP]]="Unchanged",6.42*Table4[[#This Row],[ISC BaseP]],IF(Table4[[#This Row],[ScopeP]]="Changed",7.52*(Table4[[#This Row],[ISC BaseP]] - 0.029) - 3.25 * POWER(Table4[[#This Row],[ISC BaseP]] - 0.02,15),NA())) -> #N/A | AN10: =IF(Table4[[#This Row],[Impact Sub ScoreP]]<=0,0,IF(Table4[[#This Row],[ScopeP]]="Unchanged",ROUNDUP(MIN((Table4[[#This Row],[Impact Sub ScoreP]]+Table4[[#This Row],[Exploitability Sub ScoreP]]),10),1),IF(Table4[[#This Row],[ScopeP]]="Changed",ROUNDUP(MIN((1.08*(Table4[[#This Row],[Impact Sub ScoreP]]+Table4[[#This Row],[Exploitability Sub ScoreP]])),10),1),NA()))) -> #N/A | AO10: =IF(Table4[[#This Row],[Impact Sub ScoreP]]<=0,0,IF(Table4[[#This Row],[ScopeP]]="Unchanged",ROUNDUP(MIN((Table4[[#This Row],[Impact Sub ScoreP]]+Table4[[#This Row],[Exploitability Sub ScoreP]]*Table4[[#This Row],[Threat Event Initiation Score]]),10),1),IF(Table4[[#This Row],[ScopeP]]="Changed",ROUNDUP(MIN((1.08*(Table4[[#This Row],[Impact Sub ScoreP]]+Table4[[#This Row],[Exploitability Sub ScoreP]]*Table4[[#This Row],[Threat Event Initiation Score]])),10),1),NA()))) -> #N/A | AP10: =IF(OR(ISBLANK(Table4[[#This Row],[Overall Risk ScoreP]]),ISNA(Table4[[#This Row],[Overall Risk ScoreP]])),"",IF(AND(Table4[[#This Row],[Overall Risk ScoreP]]>=9,Table4[[#This Row],[Overall Risk ScoreP]]<=10),"CRITICAL",IF(AND(Table4[[#This Row],[Overall Risk ScoreP]]>=7,Table4[[#This Row],[Overall Risk ScoreP]]<=8.9),"HIGH",IF(AND(Table4[[#This Row],[Overall Risk ScoreP]]>=4,Table4[[#This Row],[Overall Risk ScoreP]]<=6.9),"MEDIUM",IF(AND(Table4[[#This Row],[Overall Risk ScoreP]]>=0.1,Table4[[#This Row],[Overall Risk ScoreP]]<=3.9),"LOW","NONE")))))
A11: 7 | B11: T04 | C11: =IF(VLOOKUP(Table4[[#This Row],[T ID]],Table5[#All],5,FALSE)="No","Not in scope",VLOOKUP(Table4[[#This Row],[T ID]],Table5[#All],2,FALSE)) -> Unauthorized modifications to Knee Balancer Software | D11: V17 | E11: =IF(VLOOKUP(Table4[[#This Row],[V ID]],Vulnerabilities[#All],3,FALSE)="No","Not in scope",VLOOKUP(Table4[[#This Row],[V ID]],Vulnerabilities[#All],2,FALSE)) -> No Static Analysis for developed code & SCA for SOUP in Application | F11: A05 | G11: =VLOOKUP(Table4[[#This Row],[A ID]],Assets[#All],3,FALSE) -> Knee balancer supporting software components (binaries, frameworks, 3rd party components, etc..) | H11: If the software components are not protected properly/exposed for access inside the mobile host with unrestricted/unauthorized access, then the modification/tampering of the software can lead to the unavailability of the application | J11: None | K11: High | L11: Low | M11: Local | N11: Low | O11: Low | P11: None | Q11: Unchanged | R11: =8.22*VLOOKUP(Table4[[#This Row],[Attack Vector]],'Reference - CVSSv3.0'!$B$6:$C$9,2,FALSE)*VLOOKUP(Table4[[#This Row],[Attack Complexity]],'Reference - CVSSv3.0'!$E$6:$F$7,2,FALSE)*(IF(Table4[[#This Row],[Scope]]="Unchanged",VLOOKUP(Table4[[#This Row],[Privileges Required]],'Reference - CVSSv3.0'!$H$6:$I$8,2,FALSE),IF(Table4[[#This Row],[Scope]]="Changed",VLOOKUP(Table4[[#This Row],[Privileges Required]],'Reference - CVSSv3.0'!$H$6:$J$8,3,FALSE),NA())))*VLOOKUP(Table4[[#This Row],[User Interaction]],'Reference - CVSSv3.0'!$L$6:$M$7,2,FALSE) -> 1.8345766 | S11: =(1 - ((1 - VLOOKUP(Table4[[#This Row],[Confidentiality]],'Reference - CVSSv3.0'!$B$15:$C$17,2,FALSE)) * (1 - VLOOKUP(Table4[[#This Row],[Integrity]],'Reference - CVSSv3.0'!$B$15:$C$17,2,FALSE)) * (1 - VLOOKUP(Table4[[#This Row],[Availability]],'Reference - CVSSv3.0'!$B$15:$C$17,2,FALSE)))) -> 0.6568 | T11: =IF(Table4[[#This Row],[Scope]]="Unchanged",6.42*Table4[[#This Row],[ISC Base]],IF(Table4[[#This Row],[Scope]]="Changed",7.52*(Table4[[#This Row],[ISC Base]] - 0.029) - 3.25 * POWER(Table4[[#This Row],[ISC Base]] - 0.02,15),NA())) -> 4.216656 | U11: =IF(Table4[[#This Row],[Impact Sub Score]]<=0,0,IF(Table4[[#This Row],[Scope]]="Unchanged",ROUNDUP(MIN((Table4[[#This Row],[Impact Sub Score]]+Table4[[#This Row],[Exploitability Sub Score]]),10),1),IF(Table4[[#This Row],[Scope]]="Changed",ROUNDUP(MIN((1.08*(Table4[[#This Row],[Impact Sub Score]]+Table4[[#This Row],[Exploitability Sub Score]])),10),1),NA()))) -> 6.1 | V11: Moderate | W11: =VLOOKUP(Table4[[#This Row],[Threat Event Initiation]],NIST_Scale_LOAI[],2,FALSE) -> 0.5 | X11: =IF(Table4[[#This Row],[Impact Sub Score]]<=0,0,IF(Table4[[#This Row],[Scope]]="Unchanged",ROUNDUP(MIN((Table4[[#This Row],[Impact Sub Score]]+Table4[[#This Row],[Exploitability Sub Score]]*Table4[[#This Row],[Threat Event Initiation Score]]),10),1),IF(Table4[[#This Row],[Scope]]="Changed",ROUNDUP(MIN((1.08*(Table4[[#This Row],[Impact Sub Score]]+Table4[[#This Row],[Exploitability Sub Score]]*Table4[[#This Row],[Threat Event Initiation Score]])),10),1),NA()))) -> 5.2 | Y11: =IF(OR(ISBLANK(Table4[[#This Row],[Overall Risk Score]]),ISNA(Table4[[#This Row],[Overall Risk Score]])),"",IF(AND(Table4[[#This Row],[Overall Risk Score]]>=9,Table4[[#This Row],[Overall Risk Score]]<=10),"CRITICAL",IF(AND(Table4[[#This Row],[Overall Risk Score]]>=7,Table4[[#This Row],[Overall Risk Score]]<=8.9),"HIGH",IF(AND(Table4[[#This Row],[Overall Risk Score]]>=4,Table4[[#This Row],[Overall Risk Score]]<=6.9),"MEDIUM",IF(AND(Table4[[#This Row],[Overall Risk Score]]>=0.1,Table4[[#This Row],[Overall Risk Score]]<=3.9),"LOW","NONE"))))) -> MEDIUM | AK11: =8.22*VLOOKUP(Table4[[#This Row],[Attack VectorP]],'Reference - CVSSv3.0'!$B$6:$C$9,2,FALSE)*VLOOKUP(Table4[[#This Row],[Attack ComplexityP]],'Reference - CVSSv3.0'!$E$6:$F$7,2,FALSE)*(IF(Table4[[#This Row],[ScopeP]]="Unchanged",VLOOKUP(Table4[[#This Row],[Privileges RequiredP]],'Reference - CVSSv3.0'!$H$6:$I$8,2,FALSE),IF(Table4[[#This Row],[ScopeP]]="Changed",VLOOKUP(Table4[[#This Row],[Privileges RequiredP]],'Reference - CVSSv3.0'!$H$6:$J$8,3,FALSE),NA())))*VLOOKUP(Table4[[#This Row],[User InteractionP]],'Reference - CVSSv3.0'!$L$6:$M$7,2,FALSE) -> #N/A | AL11: =(1 - ((1 - VLOOKUP(Table4[[#This Row],[ConfidentialityP]],'Reference - CVSSv3.0'!$B$15:$C$17,2,FALSE)) * (1 - VLOOKUP(Table4[[#This Row],[IntegrityP]],'Reference - CVSSv3.0'!$B$15:$C$17,2,FALSE)) * (1 - VLOOKUP(Table4[[#This Row],[AvailabilityP]],'Reference - CVSSv3.0'!$B$15:$C$17,2,FALSE)))) -> #N/A | AM11: =IF(Table4[[#This Row],[ScopeP]]="Unchanged",6.42*Table4[[#This Row],[ISC BaseP]],IF(Table4[[#This Row],[ScopeP]]="Changed",7.52*(Table4[[#This Row],[ISC BaseP]] - 0.029) - 3.25 * POWER(Table4[[#This Row],[ISC BaseP]] - 0.02,15),NA())) -> #N/A | AN11: =IF(Table4[[#This Row],[Impact Sub ScoreP]]<=0,0,IF(Table4[[#This Row],[ScopeP]]="Unchanged",ROUNDUP(MIN((Table4[[#This Row],[Impact Sub ScoreP]]+Table4[[#This Row],[Exploitability Sub ScoreP]]),10),1),IF(Table4[[#This Row],[ScopeP]]="Changed",ROUNDUP(MIN((1.08*(Table4[[#This Row],[Impact Sub ScoreP]]+Table4[[#This Row],[Exploitability Sub ScoreP]])),10),1),NA()))) -> #N/A | AO11: =IF(Table4[[#This Row],[Impact Sub ScoreP]]<=0,0,IF(Table4[[#This Row],[ScopeP]]="Unchanged",ROUNDUP(MIN((Table4[[#This Row],[Impact Sub ScoreP]]+Table4[[#This Row],[Exploitability Sub ScoreP]]*Table4[[#This Row],[Threat Event Initiation Score]]),10),1),IF(Table4[[#This Row],[ScopeP]]="Changed",ROUNDUP(MIN((1.08*(Table4[[#This Row],[Impact Sub ScoreP]]+Table4[[#This Row],[Exploitability Sub ScoreP]]*Table4[[#This Row],[Threat Event Initiation Score]])),10),1),NA()))) -> #N/A | AP11: =IF(OR(ISBLANK(Table4[[#This Row],[Overall Risk ScoreP]]),ISNA(Table4[[#This Row],[Overall Risk ScoreP]])),"",IF(AND(Table4[[#This Row],[Overall Risk ScoreP]]>=9,Table4[[#This Row],[Overall Risk ScoreP]]<=10),"CRITICAL",IF(AND(Table4[[#This Row],[Overall Risk ScoreP]]>=7,Table4[[#This Row],[Overall Risk ScoreP]]<=8.9),"HIGH",IF(AND(Table4[[#This Row],[Overall Risk ScoreP]]>=4,Table4[[#This Row],[Overall Risk ScoreP]]<=6.9),"MEDIUM",IF(AND(Table4[[#This Row],[Overall Risk ScoreP]]>=0.1,Table4[[#This Row],[Overall Risk ScoreP]]<=3.9),"LOW","NONE")))))
